{"uuid": "b6d02102-cbe9-454d-9923-618105431669", "children": ["e46013f9-7584-4551-9cc0-bc17b6f86b72"], "befores": [{"name": "get_new_user", "status": "failed", "statusDetails": {"message": "Failed: User creation failed, 'accessToken' not found in response.\n", "trace": "  File \"C:\\Users\\xdsla\\AppData\\Local\\Packages\\PythonSoftwareFoundation.Python.3.11_qbz5n2kfra8p0\\LocalCache\\local-packages\\Python311\\site-packages\\pluggy\\_callers.py\", line 166, in _multicall\n    teardown.throw(outcome._exception)\n  File \"C:\\Users\\xdsla\\AppData\\Local\\Packages\\PythonSoftwareFoundation.Python.3.11_qbz5n2kfra8p0\\LocalCache\\local-packages\\Python311\\site-packages\\_pytest\\setuponly.py\", line 36, in pytest_fixture_setup\n    return (yield)\n            ^^^^^\n  File \"C:\\Users\\xdsla\\AppData\\Local\\Packages\\PythonSoftwareFoundation.Python.3.11_qbz5n2kfra8p0\\LocalCache\\local-packages\\Python311\\site-packages\\pluggy\\_callers.py\", line 102, in _multicall\n    res = hook_impl.function(*args)\n          ^^^^^^^^^^^^^^^^^^^^^^^^^\n  File \"C:\\Users\\xdsla\\AppData\\Local\\Packages\\PythonSoftwareFoundation.Python.3.11_qbz5n2kfra8p0\\LocalCache\\local-packages\\Python311\\site-packages\\_pytest\\fixtures.py\", line 1132, in pytest_fixture_setup\n    result = call_fixture_func(fixturefunc, request, kwargs)\n             ^^^^^^^^^^^^^^^^^^^^^^^^^^^^^^^^^^^^^^^^^^^^^^^\n  File \"C:\\Users\\xdsla\\AppData\\Local\\Packages\\PythonSoftwareFoundation.Python.3.11_qbz5n2kfra8p0\\LocalCache\\local-packages\\Python311\\site-packages\\_pytest\\fixtures.py\", line 906, in call_fixture_func\n    fixture_result = next(generator)\n                     ^^^^^^^^^^^^^^^\n  File \"C:\\Users\\xdsla\\PycharmProjects\\Diplom_3\\tests\\conftest.py\", line 41, in get_new_user\n    pytest.fail(\"User creation failed, 'accessToken' not found in response.\")\n  File \"C:\\Users\\xdsla\\AppData\\Local\\Packages\\PythonSoftwareFoundation.Python.3.11_qbz5n2kfra8p0\\LocalCache\\local-packages\\Python311\\site-packages\\_pytest\\outcomes.py\", line 166, in fail\n    raise Failed(msg=reason, pytrace=pytrace)\n"}, "steps": [{"name": "Генерация фейковых кредов для регистрации пользователя", "status": "passed", "start": 1719806132081, "stop": 1719806132160}, {"name": "Регистрация нового пользователя", "status": "passed", "parameters": [{"name": "user_data", "value": "{'email': 'borisovaraisa@example.net', 'password': '^#q9%Vsv%4', 'name': 'svetozar1993'}"}], "start": 1719806132160, "stop": 1719806133094}], "start": 1719806132081, "stop": 1719806133094}], "start": 1719806132081, "stop": 1719806133108}