{"uuid": "a0687145-b6ab-40b3-9353-509a690a834a", "children": ["c0f5575e-7a9d-456d-962d-c18f59e10cca"], "befores": [{"name": "get_driver", "status": "broken", "statusDetails": {"message": "selenium.common.exceptions.WebDriverException: Message: Process unexpectedly closed with status 0\n\n", "trace": "  File \"C:\\Users\\xdsla\\AppData\\Local\\Packages\\PythonSoftwareFoundation.Python.3.11_qbz5n2kfra8p0\\LocalCache\\local-packages\\Python311\\site-packages\\pluggy\\_callers.py\", line 166, in _multicall\n    teardown.throw(outcome._exception)\n  File \"C:\\Users\\xdsla\\AppData\\Local\\Packages\\PythonSoftwareFoundation.Python.3.11_qbz5n2kfra8p0\\LocalCache\\local-packages\\Python311\\site-packages\\_pytest\\setuponly.py\", line 36, in pytest_fixture_setup\n    return (yield)\n            ^^^^^\n  File \"C:\\Users\\xdsla\\AppData\\Local\\Packages\\PythonSoftwareFoundation.Python.3.11_qbz5n2kfra8p0\\LocalCache\\local-packages\\Python311\\site-packages\\pluggy\\_callers.py\", line 102, in _multicall\n    res = hook_impl.function(*args)\n          ^^^^^^^^^^^^^^^^^^^^^^^^^\n  File \"C:\\Users\\xdsla\\AppData\\Local\\Packages\\PythonSoftwareFoundation.Python.3.11_qbz5n2kfra8p0\\LocalCache\\local-packages\\Python311\\site-packages\\_pytest\\fixtures.py\", line 1132, in pytest_fixture_setup\n    result = call_fixture_func(fixturefunc, request, kwargs)\n             ^^^^^^^^^^^^^^^^^^^^^^^^^^^^^^^^^^^^^^^^^^^^^^^\n  File \"C:\\Users\\xdsla\\AppData\\Local\\Packages\\PythonSoftwareFoundation.Python.3.11_qbz5n2kfra8p0\\LocalCache\\local-packages\\Python311\\site-packages\\_pytest\\fixtures.py\", line 906, in call_fixture_func\n    fixture_result = next(generator)\n                     ^^^^^^^^^^^^^^^\n  File \"C:\\Users\\xdsla\\PycharmProjects\\Diplom_3\\tests\\conftest.py\", line 24, in get_driver\n    driver = webdriver.Firefox(service=FirefoxService(GeckoDriverManager().install()), options=options)\n             ^^^^^^^^^^^^^^^^^^^^^^^^^^^^^^^^^^^^^^^^^^^^^^^^^^^^^^^^^^^^^^^^^^^^^^^^^^^^^^^^^^^^^^^^^^\n  File \"C:\\Users\\xdsla\\AppData\\Local\\Packages\\PythonSoftwareFoundation.Python.3.11_qbz5n2kfra8p0\\LocalCache\\local-packages\\Python311\\site-packages\\selenium\\webdriver\\firefox\\webdriver.py\", line 74, in __init__\n    super().__init__(command_executor=executor, options=options)\n  File \"C:\\Users\\xdsla\\AppData\\Local\\Packages\\PythonSoftwareFoundation.Python.3.11_qbz5n2kfra8p0\\LocalCache\\local-packages\\Python311\\site-packages\\selenium\\webdriver\\remote\\webdriver.py\", line 208, in __init__\n    self.start_session(capabilities)\n  File \"C:\\Users\\xdsla\\AppData\\Local\\Packages\\PythonSoftwareFoundation.Python.3.11_qbz5n2kfra8p0\\LocalCache\\local-packages\\Python311\\site-packages\\selenium\\webdriver\\remote\\webdriver.py\", line 292, in start_session\n    response = self.execute(Command.NEW_SESSION, caps)[\"value\"]\n               ^^^^^^^^^^^^^^^^^^^^^^^^^^^^^^^^^^^^^^^\n  File \"C:\\Users\\xdsla\\AppData\\Local\\Packages\\PythonSoftwareFoundation.Python.3.11_qbz5n2kfra8p0\\LocalCache\\local-packages\\Python311\\site-packages\\selenium\\webdriver\\remote\\webdriver.py\", line 347, in execute\n    self.error_handler.check_response(response)\n  File \"C:\\Users\\xdsla\\AppData\\Local\\Packages\\PythonSoftwareFoundation.Python.3.11_qbz5n2kfra8p0\\LocalCache\\local-packages\\Python311\\site-packages\\selenium\\webdriver\\remote\\errorhandler.py\", line 229, in check_response\n    raise exception_class(message, screen, stacktrace)\n"}, "start": 1719395420238, "stop": 1719395431640}], "start": 1719395420238, "stop": 1719395431829}